Workbook
Name _ftn1: 'Harms table'!#REF!
Name _ftn2: 'Harms table'!#REF!
Name _ftn3: 'sales tables'!$B$21
Name _ftn4: 'sales tables'!$B$22
Name _ftn5: 'sales tables'!$B$23
Name _ftnref1: 'Harms table'!$I$6
Name _ftnref2: 'Harms table'!$I$23
Name _ftnref4: 'sales tables'!$B$12
Name _ftnref5: 'sales tables'!$B$15

Sheet Config
A1: PSUR Complaint & Sales Surveillance Workbook
A2: Configuration & Instructions
A4: ⚙️ CONFIGURATION
F5: Occurrence Rate Scale (RACT Standard)
B6: Setting | C6: Value | D6: Notes | F6: Occurrence Code | G6: Rate Range | H6: Max Expected Rate
B7: Product / Device Name | C7: Global® Total® for Fertilization | D7: e.g., ALLY UPS Micropipettes | F7: O5 | G7: OHarm > 10% | H7: 1
B8: Surveillance Start Date | C8: 44743 | D8: First day of surveillance (e.g., 01/04/2022) | F8: O4 | G8: 1% < OHarm ≤ 10% | H8: 0.1
B9: Surveillance End Date | C9: 45838 | D9: Last day of surveillance window | F9: O3 | G9: 0.1% < OHarm ≤ 1% | H9: 0.01
B10: Update Frequency | C10: Annual | D10: Enter: Annual or Biennial | F10: O2 | G10: 0.01% < OHarm ≤ 0.1% | H10: 0.001
B11: Historical Data Start Date | D11: Optional – First day of historical period (leave blank if none)
B12: Historical Data End Date | D12: Optional – Last day of historical period (should precede Surveillance Start)
A14: 📋 PSUR COVER PAGE METADATA
B15: Manufacturer Information | C15: Value | D15: Notes
B16: Company Name | C16: CooperSurgical, Inc. | D16: Pre-filled from PSUR template (static)
B17: Company Address | C17: CooperSurgical, Inc., 95 Corporate Drive, Trumbull, CT 06611, United States of America | D17: Pre-filled from PSUR template (static)
B18: Manufacturer SRN | C18: US-MF-000002607 | D18: Pre-filled from PSUR template (static)
B19: Authorized Representative | C19: CooperSurgical Distribution B.V., Celsiusweg 35, 5928 PR Venlo, The Netherlands | D19: Pre-filled from PSUR template (static)
B20: AR SRN | C20: NL-AR-0000000059 | D20: Pre-filled from PSUR template (static)
B21: Notified Body Name | C21: BSI Group The Netherlands B.V. | D21: Pre-filled from PSUR template (static)
B22: Notified Body Number | C22: 2797 | D22: Pre-filled from PSUR template (static)
B23: Certificate Number | C23: N/A - Not Under EU MDR | D23: User input — Certificate number (varies per PSUR cycle)
B25: Device Information | C25: Value | D25: Notes
B26: Basic UDI-DI | C26: N/A - Not Under EU MDR | D26: Basic Unique Device Identification
B27: Device Trade Name | C27: =IF(C7="","",C7) -> Global® Total® for Fertilization | D27: Auto-linked from Product Name above
B28: EMDN Code | C28: N/A - Not Under EU MDR | D28: European Medical Device Nomenclature code
B29: GMDN Code | C29: N/A - Not Under EU MDR | D29: Global Medical Device Nomenclature code
B30: Device Risk Class | C30: Iib | D30: MDR Classification (I, IIa, IIb, III)
B31: Data Collection Period | C31: =IF(OR(C8="",C9=""),"",TEXT(C8,"dd-mmm-yyyy")&" to "&TEXT(C9,"dd-mmm-yyyy")) -> 01-Jul-2022 to 30-Jun-2025 | D31: Auto-calculated from surveillance dates above
B32: PSUR Cadence | C32: =IF(C10="","",C10) -> Annual | D32: Auto-linked from Update Frequency above
B33: ⬆ BLUE cells with YELLOW background = User inputs | GREEN text = Auto-linked from settings above | F33: O1 | G33: OHarm ≤ 0.01% | H33: 0.0001
F35: Auto-calculated in the Harms table columns I & J based on actual complaint rates.
A38: 📖 DATA ENTRY INSTRUCTIONS
B40: OVERVIEW
B41: This workbook automates PSUR (Periodic Safety Update Report) surveillance. You only enter data in TWO sheets — all other tabs auto-calculate.
B43: WORKBOOK STRUCTURE
B44: Sheet | C44: Type | D44: Description
B45: Config (this sheet) | C45: ⚙️ Settings | D45: Surveillance settings, RACT values, and this instruction guide
B46: complaints | C46: ✏️ INPUT | D46: Enter complaint records in columns A–D. Columns E–F auto-populate.
B47: Sales | C47: ✏️ INPUT | D47: Enter sales data in columns A–D (Country, Month, Quantity, Year).
B48: Harms table | C48: 🔒 AUTO | D48: Complaint rates by Medical Device Problem — annual & biennial tables (protected)
...

Sheet complaints
A1: Complaint Number | B1: CSI Notification Date | C1: Description | D1: Symptom Code | E1: Medical Device Problem | F1: Harm | G1: IMDRF MDP Code | H1: Investigation Findings | I1: Investigation Conclusion
A2: 2023-03-0000416 | B2: 45006 | C2: The customer is seeing particles in the dish, he was having this particles observed in embryo culture from 11th of this month. He is using on K-system G210 and G185 incubators for culture. He is ruling out different parameters one by one to resolve this issues. Initially he was suspecting the GPS dishes. Yesterday he made droplets of sperm washing from origio all the dishes he is using from different brands and found no artefacts after 24 hr incubation. Today he made droplets with global media and he is finding some artefacts under observation. He thinks it’s the cause of the particles in culture during the course he had done culture swab from all areas and lab equipment including incubator and culture media but no growth reported by infection control. (Photos attached)_x000D_ _x000D_ ANY PATIENT INJURY OR IMPACT TO THE GAMETE OR EMBRYO? No_x000D_ WAS A MEDICAL OR PROCEDURAL INTERVENTION REQUIRED? No | D2: foreignmaterial | E2: {=IF(D2<>"",IFERROR(VLOOKUP(D2,Codes!$K$2:$L$409,2,FALSE),"UNKNOWN - "&D2),IF(C2="","",IFERROR(_xlfn.IFS(ISNUMBER(SEARCH("broken button",C2)),"Break",ISNUMBER(SEARCH("broken handle",C2)),"Break",ISNUMBER(SEARCH("shipping damage",C2)),"Break",ISNUMBER(SEARCH("broken",C2)),"Break",ISNUMBER(SEARCH("crack",C2)),"Break",ISNUMBER(SEARCH("snap",C2)),"Break",ISNUMBER(SEARCH("fracture",C2)),"Break",ISNUMBER(SEARCH("bent",C2)),"Material Twisted/Bent",ISNUMBER(SEARCH("twisted",C2)),"Material Twisted/Bent",ISNUMBER(SEARCH("component separat",C2)),"Material Separation",ISNUMBER(SEARCH("separat",C2)),"Material Separation",ISNUMBER(SEARCH("connection",C2)),"Loose or Intermittent Connection",ISNUMBER(SEARCH("loose",C2)),"Loose or Intermittent Connection",ISNUMBER(SEARCH("damaged packaging",C2)),"Packaging Problem",ISNUMBER(SEARCH("packaging",C2)),"Packaging Problem",ISNUMBER(SEARCH("discoloration",C2)),"Contamination",ISNUMBER(SEARCH("tarnish",C2)),"Contamination",ISNUMBER(SEARCH("stain",C2)),"Contamination",ISNUMBER(SEARCH("foreign material",C2)),"Contamination",ISNUMBER(SEARCH("contamina",C2)),"Contamination",ISNUMBER(SEARCH("overheat",C2)),"Overheating of Device",ISNUMBER(SEARCH("excessive heat",C2)),"Overheating of Device",ISNUMBER(SEARCH("hot",C2)),"Overheating of Device",ISNUMBER(SEARCH("noise",C2)),"Noise, Audible",ISNUMBER(SEARCH("sound",C2)),"Noise, Audible",ISNUMBER(SEARCH("loud",C2)),"Noise, Audible",ISNUMBER(SEARCH("fray",C2)),"Material Frayed",ISNUMBER(SEARCH("hole",C2)),"Material Frayed",ISNUMBER(SEARCH("tear",C2)),"Material Frayed",ISNUMBER(SEARCH("worn",C2)),"Material Frayed",ISNUMBER(SEARCH("intermittent",C2)),"Difficult or Delayed Activation",ISNUMBER(SEARCH("delay",C2)),"Difficult or Delayed Activation",ISNUMBER(SEARCH("label",C2)),"Device Markings/Labelling Problem",ISNUMBER(SEARCH("marking",C2)),"Device Markings/Labelling Problem",ISNUMBER(SEARCH("lacerat",C2)),"Defective Device",ISNUMBER(SEARCH("cut",C2)),"Defective Device",ISNUMBER(SEARCH("leak",C2)),"Fluid/Blood Leak",ISNUMBER(SEARCH("missing",C2)),"Component Missing",ISNUMBER(SEARCH("power",C2)),"Complete Loss of Power",ISNUMBER(SEARCH("will not turn on",C2)),"Complete Loss of Power",ISNUMBER(SEARCH("won't turn on",C2)),"Complete Loss of Power",ISNUMBER(SEARCH("does not turn on",C2)),"Complete Loss of Power",ISNUMBER(SEARCH("electrical",C2)),"Electrical Power Problem",ISNUMBER(SEARCH("pressure",C2)),"Detachment of Device or Device Component",ISNUMBER(SEARCH("slip",C2)),"Detachment of Device or Device Component",ISNUMBER(SEARCH("detach",C2)),"Detachment of Device or Device Component",ISNUMBER(SEARCH("stick",C2)),"Mechanical Jam",ISNUMBER(SEARCH("jam",C2)),"Mechanical Jam",ISNUMBER(SEARCH("rigid",C2)),"Mechanical Jam",ISNUMBER(SEARCH("rust",C2)),"Corroded",ISNUMBER(SEARCH("corrod",C2)),"Corroded",ISNUMBER(SEARCH("corrosion",C2)),"Corroded",ISNUMBER(SEARCH("alignment",C2)),"Defective Device",ISNUMBER(SEARCH("adjust",C2)),"Defective Device",ISNUMBER(SEARCH("perform",C2)),"Defective Device",ISNUMBER(SEARCH("malfunction",C2)),"Defective Device",ISNUMBER(SEARCH("defect",C2)),"Defective Device",ISNUMBER(SEARCH("fail",C2)),"Defective Device",ISNUMBER(SEARCH("not work",C2)),"Defective Device",ISNUMBER(SEARCH("doesn't work",C2)),"Defective Device",TRUE,"UNKNOWN"),"UNKNOWN")))} -> Contamination | F2: =IF(E2="","","No Clinical Signs, Symptoms or Conditions") -> No Clinical Signs, Symptoms or Conditions | G2: =IF(E2="","",IFERROR(VLOOKUP(E2,Codes!$L$2:$N$409,3,FALSE),"—")) -> A1801
A3: 2023-04-0000158 | B3: 45026 | C3: When using the culture media, customer is seeing particles / artefacts in the dish. | D3: particles | E3: {=IF(D3<>"",IFERROR(VLOOKUP(D3,Codes!$K$2:$L$409,2,FALSE),"UNKNOWN - "&D3),IF(C3="","",IFERROR(_xlfn.IFS(ISNUMBER(SEARCH("broken button",C3)),"Break",ISNUMBER(SEARCH("broken handle",C3)),"Break",ISNUMBER(SEARCH("shipping damage",C3)),"Break",ISNUMBER(SEARCH("broken",C3)),"Break",ISNUMBER(SEARCH("crack",C3)),"Break",ISNUMBER(SEARCH("snap",C3)),"Break",ISNUMBER(SEARCH("fracture",C3)),"Break",ISNUMBER(SEARCH("bent",C3)),"Material Twisted/Bent",ISNUMBER(SEARCH("twisted",C3)),"Material Twisted/Bent",ISNUMBER(SEARCH("component separat",C3)),"Material Separation",ISNUMBER(SEARCH("separat",C3)),"Material Separation",ISNUMBER(SEARCH("connection",C3)),"Loose or Intermittent Connection",ISNUMBER(SEARCH("loose",C3)),"Loose or Intermittent Connection",ISNUMBER(SEARCH("damaged packaging",C3)),"Packaging Problem",ISNUMBER(SEARCH("packaging",C3)),"Packaging Problem",ISNUMBER(SEARCH("discoloration",C3)),"Contamination",ISNUMBER(SEARCH("tarnish",C3)),"Contamination",ISNUMBER(SEARCH("stain",C3)),"Contamination",ISNUMBER(SEARCH("foreign material",C3)),"Contamination",ISNUMBER(SEARCH("contamina",C3)),"Contamination",ISNUMBER(SEARCH("overheat",C3)),"Overheating of Device",ISNUMBER(SEARCH("excessive heat",C3)),"Overheating of Device",ISNUMBER(SEARCH("hot",C3)),"Overheating of Device",ISNUMBER(SEARCH("noise",C3)),"Noise, Audible",ISNUMBER(SEARCH("sound",C3)),"Noise, Audible",ISNUMBER(SEARCH("loud",C3)),"Noise, Audible",ISNUMBER(SEARCH("fray",C3)),"Material Frayed",ISNUMBER(SEARCH("hole",C3)),"Material Frayed",ISNUMBER(SEARCH("tear",C3)),"Material Frayed",ISNUMBER(SEARCH("worn",C3)),"Material Frayed",ISNUMBER(SEARCH("intermittent",C3)),"Difficult or Delayed Activation",ISNUMBER(SEARCH("delay",C3)),"Difficult or Delayed Activation",ISNUMBER(SEARCH("label",C3)),"Device Markings/Labelling Problem",ISNUMBER(SEARCH("marking",C3)),"Device Markings/Labelling Problem",ISNUMBER(SEARCH("lacerat",C3)),"Defective Device",ISNUMBER(SEARCH("cut",C3)),"Defective Device",ISNUMBER(SEARCH("leak",C3)),"Fluid/Blood Leak",ISNUMBER(SEARCH("missing",C3)),"Component Missing",ISNUMBER(SEARCH("power",C3)),"Complete Loss of Power",ISNUMBER(SEARCH("will not turn on",C3)),"Complete Loss of Power",ISNUMBER(SEARCH("won't turn on",C3)),"Complete Loss of Power",ISNUMBER(SEARCH("does not turn on",C3)),"Complete Loss of Power",ISNUMBER(SEARCH("electrical",C3)),"Electrical Power Problem",ISNUMBER(SEARCH("pressure",C3)),"Detachment of Device or Device Component",ISNUMBER(SEARCH("slip",C3)),"Detachment of Device or Device Component",ISNUMBER(SEARCH("detach",C3)),"Detachment of Device or Device Component",ISNUMBER(SEARCH("stick",C3)),"Mechanical Jam",ISNUMBER(SEARCH("jam",C3)),"Mechanical Jam",ISNUMBER(SEARCH("rigid",C3)),"Mechanical Jam",ISNUMBER(SEARCH("rust",C3)),"Corroded",ISNUMBER(SEARCH("corrod",C3)),"Corroded",ISNUMBER(SEARCH("corrosion",C3)),"Corroded",ISNUMBER(SEARCH("alignment",C3)),"Defective Device",ISNUMBER(SEARCH("adjust",C3)),"Defective Device",ISNUMBER(SEARCH("perform",C3)),"Defective Device",ISNUMBER(SEARCH("malfunction",C3)),"Defective Device",ISNUMBER(SEARCH("defect",C3)),"Defective Device",ISNUMBER(SEARCH("fail",C3)),"Defective Device",ISNUMBER(SEARCH("not work",C3)),"Defective Device",ISNUMBER(SEARCH("doesn't work",C3)),"Defective Device",TRUE,"UNKNOWN"),"UNKNOWN")))} -> UNKNOWN - particles | F3: =IF(E3="","","No Clinical Signs, Symptoms or Conditions") -> No Clinical Signs, Symptoms or Conditions | G3: =IF(E3="","",IFERROR(VLOOKUP(E3,Codes!$L$2:$N$409,3,FALSE),"—")) -> —
A4: 2023-05-0000145 | B4: 45051 | C4: Product was darker pink than normal | D4: colorph | E4: {=IF(D4<>"",IFERROR(VLOOKUP(D4,Codes!$K$2:$L$409,2,FALSE),"UNKNOWN - "&D4),IF(C4="","",IFERROR(_xlfn.IFS(ISNUMBER(SEARCH("broken button",C4)),"Break",ISNUMBER(SEARCH("broken handle",C4)),"Break",ISNUMBER(SEARCH("shipping damage",C4)),"Break",ISNUMBER(SEARCH("broken",C4)),"Break",ISNUMBER(SEARCH("crack",C4)),"Break",ISNUMBER(SEARCH("snap",C4)),"Break",ISNUMBER(SEARCH("fracture",C4)),"Break",ISNUMBER(SEARCH("bent",C4)),"Material Twisted/Bent",ISNUMBER(SEARCH("twisted",C4)),"Material Twisted/Bent",ISNUMBER(SEARCH("component separat",C4)),"Material Separation",ISNUMBER(SEARCH("separat",C4)),"Material Separation",ISNUMBER(SEARCH("connection",C4)),"Loose or Intermittent Connection",ISNUMBER(SEARCH("loose",C4)),"Loose or Intermittent Connection",ISNUMBER(SEARCH("damaged packaging",C4)),"Packaging Problem",ISNUMBER(SEARCH("packaging",C4)),"Packaging Problem",ISNUMBER(SEARCH("discoloration",C4)),"Contamination",ISNUMBER(SEARCH("tarnish",C4)),"Contamination",ISNUMBER(SEARCH("stain",C4)),"Contamination",ISNUMBER(SEARCH("foreign material",C4)),"Contamination",ISNUMBER(SEARCH("contamina",C4)),"Contamination",ISNUMBER(SEARCH("overheat",C4)),"Overheating of Device",ISNUMBER(SEARCH("excessive heat",C4)),"Overheating of Device",ISNUMBER(SEARCH("hot",C4)),"Overheating of Device",ISNUMBER(SEARCH("noise",C4)),"Noise, Audible",ISNUMBER(SEARCH("sound",C4)),"Noise, Audible",ISNUMBER(SEARCH("loud",C4)),"Noise, Audible",ISNUMBER(SEARCH("fray",C4)),"Material Frayed",ISNUMBER(SEARCH("hole",C4)),"Material Frayed",ISNUMBER(SEARCH("tear",C4)),"Material Frayed",ISNUMBER(SEARCH("worn",C4)),"Material Frayed",ISNUMBER(SEARCH("intermittent",C4)),"Difficult or Delayed Activation",ISNUMBER(SEARCH("delay",C4)),"Difficult or Delayed Activation",ISNUMBER(SEARCH("label",C4)),"Device Markings/Labelling Problem",ISNUMBER(SEARCH("marking",C4)),"Device Markings/Labelling Problem",ISNUMBER(SEARCH("lacerat",C4)),"Defective Device",ISNUMBER(SEARCH("cut",C4)),"Defective Device",ISNUMBER(SEARCH("leak",C4)),"Fluid/Blood Leak",ISNUMBER(SEARCH("missing",C4)),"Component Missing",ISNUMBER(SEARCH("power",C4)),"Complete Loss of Power",ISNUMBER(SEARCH("will not turn on",C4)),"Complete Loss of Power",ISNUMBER(SEARCH("won't turn on",C4)),"Complete Loss of Power",ISNUMBER(SEARCH("does not turn on",C4)),"Complete Loss of Power",ISNUMBER(SEARCH("electrical",C4)),"Electrical Power Problem",ISNUMBER(SEARCH("pressure",C4)),"Detachment of Device or Device Component",ISNUMBER(SEARCH("slip",C4)),"Detachment of Device or Device Component",ISNUMBER(SEARCH("detach",C4)),"Detachment of Device or Device Component",ISNUMBER(SEARCH("stick",C4)),"Mechanical Jam",ISNUMBER(SEARCH("jam",C4)),"Mechanical Jam",ISNUMBER(SEARCH("rigid",C4)),"Mechanical Jam",ISNUMBER(SEARCH("rust",C4)),"Corroded",ISNUMBER(SEARCH("corrod",C4)),"Corroded",ISNUMBER(SEARCH("corrosion",C4)),"Corroded",ISNUMBER(SEARCH("alignment",C4)),"Defective Device",ISNUMBER(SEARCH("adjust",C4)),"Defective Device",ISNUMBER(SEARCH("perform",C4)),"Defective Device",ISNUMBER(SEARCH("malfunction",C4)),"Defective Device",ISNUMBER(SEARCH("defect",C4)),"Defective Device",ISNUMBER(SEARCH("fail",C4)),"Defective Device",ISNUMBER(SEARCH("not work",C4)),"Defective Device",ISNUMBER(SEARCH("doesn't work",C4)),"Defective Device",TRUE,"UNKNOWN"),"UNKNOWN")))} -> UNKNOWN - colorph | F4: =IF(E4="","","No Clinical Signs, Symptoms or Conditions") -> No Clinical Signs, Symptoms or Conditions | G4: =IF(E4="","",IFERROR(VLOOKUP(E4,Codes!$L$2:$N$409,3,FALSE),"—")) -> —
A5: 2023-05-0000540 | B5: 45072 | C5: Product arrived and is a yellow color. just received; did not use. | D5: colorph | E5: {=IF(D5<>"",IFERROR(VLOOKUP(D5,Codes!$K$2:$L$409,2,FALSE),"UNKNOWN - "&D5),IF(C5="","",IFERROR(_xlfn.IFS(ISNUMBER(SEARCH("broken button",C5)),"Break",ISNUMBER(SEARCH("broken handle",C5)),"Break",ISNUMBER(SEARCH("shipping damage",C5)),"Break",ISNUMBER(SEARCH("broken",C5)),"Break",ISNUMBER(SEARCH("crack",C5)),"Break",ISNUMBER(SEARCH("snap",C5)),"Break",ISNUMBER(SEARCH("fracture",C5)),"Break",ISNUMBER(SEARCH("bent",C5)),"Material Twisted/Bent",ISNUMBER(SEARCH("twisted",C5)),"Material Twisted/Bent",ISNUMBER(SEARCH("component separat",C5)),"Material Separation",ISNUMBER(SEARCH("separat",C5)),"Material Separation",ISNUMBER(SEARCH("connection",C5)),"Loose or Intermittent Connection",ISNUMBER(SEARCH("loose",C5)),"Loose or Intermittent Connection",ISNUMBER(SEARCH("damaged packaging",C5)),"Packaging Problem",ISNUMBER(SEARCH("packaging",C5)),"Packaging Problem",ISNUMBER(SEARCH("discoloration",C5)),"Contamination",ISNUMBER(SEARCH("tarnish",C5)),"Contamination",ISNUMBER(SEARCH("stain",C5)),"Contamination",ISNUMBER(SEARCH("foreign material",C5)),"Contamination",ISNUMBER(SEARCH("contamina",C5)),"Contamination",ISNUMBER(SEARCH("overheat",C5)),"Overheating of Device",ISNUMBER(SEARCH("excessive heat",C5)),"Overheating of Device",ISNUMBER(SEARCH("hot",C5)),"Overheating of Device",ISNUMBER(SEARCH("noise",C5)),"Noise, Audible",ISNUMBER(SEARCH("sound",C5)),"Noise, Audible",ISNUMBER(SEARCH("loud",C5)),"Noise, Audible",ISNUMBER(SEARCH("fray",C5)),"Material Frayed",ISNUMBER(SEARCH("hole",C5)),"Material Frayed",ISNUMBER(SEARCH("tear",C5)),"Material Frayed",ISNUMBER(SEARCH("worn",C5)),"Material Frayed",ISNUMBER(SEARCH("intermittent",C5)),"Difficult or Delayed Activation",ISNUMBER(SEARCH("delay",C5)),"Difficult or Delayed Activation",ISNUMBER(SEARCH("label",C5)),"Device Markings/Labelling Problem",ISNUMBER(SEARCH("marking",C5)),"Device Markings/Labelling Problem",ISNUMBER(SEARCH("lacerat",C5)),"Defective Device",ISNUMBER(SEARCH("cut",C5)),"Defective Device",ISNUMBER(SEARCH("leak",C5)),"Fluid/Blood Leak",ISNUMBER(SEARCH("missing",C5)),"Component Missing",ISNUMBER(SEARCH("power",C5)),"Complete Loss of Power",ISNUMBER(SEARCH("will not turn on",C5)),"Complete Loss of Power",ISNUMBER(SEARCH("won't turn on",C5)),"Complete Loss of Power",ISNUMBER(SEARCH("does not turn on",C5)),"Complete Loss of Power",ISNUMBER(SEARCH("electrical",C5)),"Electrical Power Problem",ISNUMBER(SEARCH("pressure",C5)),"Detachment of Device or Device Component",ISNUMBER(SEARCH("slip",C5)),"Detachment of Device or Device Component",ISNUMBER(SEARCH("detach",C5)),"Detachment of Device or Device Component",ISNUMBER(SEARCH("stick",C5)),"Mechanical Jam",ISNUMBER(SEARCH("jam",C5)),"Mechanical Jam",ISNUMBER(SEARCH("rigid",C5)),"Mechanical Jam",ISNUMBER(SEARCH("rust",C5)),"Corroded",ISNUMBER(SEARCH("corrod",C5)),"Corroded",ISNUMBER(SEARCH("corrosion",C5)),"Corroded",ISNUMBER(SEARCH("alignment",C5)),"Defective Device",ISNUMBER(SEARCH("adjust",C5)),"Defective Device",ISNUMBER(SEARCH("perform",C5)),"Defective Device",ISNUMBER(SEARCH("malfunction",C5)),"Defective Device",ISNUMBER(SEARCH("defect",C5)),"Defective Device",ISNUMBER(SEARCH("fail",C5)),"Defective Device",ISNUMBER(SEARCH("not work",C5)),"Defective Device",ISNUMBER(SEARCH("doesn't work",C5)),"Defective Device",TRUE,"UNKNOWN"),"UNKNOWN")))} -> UNKNOWN - colorph | F5: =IF(E5="","","No Clinical Signs, Symptoms or Conditions") -> No Clinical Signs, Symptoms or Conditions | G5: =IF(E5="","",IFERROR(VLOOKUP(E5,Codes!$L$2:$N$409,3,FALSE),"—")) -> —
A6: 2023-05-0000618 | B6: 45076 | C6: Media is all more yellow than previous lots._x000D_ _x000D_ ANY PATIENT INJURY OR IMPACT TO THE GAMETE OR EMBRYO? No_x000D_ WAS A MEDICAL OR PROCEDURAL INTERVENTION REQUIRED? No | D6: colorph | E6: {=IF(D6<>"",IFERROR(VLOOKUP(D6,Codes!$K$2:$L$409,2,FALSE),"UNKNOWN - "&D6),IF(C6="","",IFERROR(_xlfn.IFS(ISNUMBER(SEARCH("broken button",C6)),"Break",ISNUMBER(SEARCH("broken handle",C6)),"Break",ISNUMBER(SEARCH("shipping damage",C6)),"Break",ISNUMBER(SEARCH("broken",C6)),"Break",ISNUMBER(SEARCH("crack",C6)),"Break",ISNUMBER(SEARCH("snap",C6)),"Break",ISNUMBER(SEARCH("fracture",C6)),"Break",ISNUMBER(SEARCH("bent",C6)),"Material Twisted/Bent",ISNUMBER(SEARCH("twisted",C6)),"Material Twisted/Bent",ISNUMBER(SEARCH("component separat",C6)),"Material Separation",ISNUMBER(SEARCH("separat",C6)),"Material Separation",ISNUMBER(SEARCH("connection",C6)),"Loose or Intermittent Connection",ISNUMBER(SEARCH("loose",C6)),"Loose or Intermittent Connection",ISNUMBER(SEARCH("damaged packaging",C6)),"Packaging Problem",ISNUMBER(SEARCH("packaging",C6)),"Packaging Problem",ISNUMBER(SEARCH("discoloration",C6)),"Contamination",ISNUMBER(SEARCH("tarnish",C6)),"Contamination",ISNUMBER(SEARCH("stain",C6)),"Contamination",ISNUMBER(SEARCH("foreign material",C6)),"Contamination",ISNUMBER(SEARCH("contamina",C6)),"Contamination",ISNUMBER(SEARCH("overheat",C6)),"Overheating of Device",ISNUMBER(SEARCH("excessive heat",C6)),"Overheating of Device",ISNUMBER(SEARCH("hot",C6)),"Overheating of Device",ISNUMBER(SEARCH("noise",C6)),"Noise, Audible",ISNUMBER(SEARCH("sound",C6)),"Noise, Audible",ISNUMBER(SEARCH("loud",C6)),"Noise, Audible",ISNUMBER(SEARCH("fray",C6)),"Material Frayed",ISNUMBER(SEARCH("hole",C6)),"Material Frayed",ISNUMBER(SEARCH("tear",C6)),"Material Frayed",ISNUMBER(SEARCH("worn",C6)),"Material Frayed",ISNUMBER(SEARCH("intermittent",C6)),"Difficult or Delayed Activation",ISNUMBER(SEARCH("delay",C6)),"Difficult or Delayed Activation",ISNUMBER(SEARCH("label",C6)),"Device Markings/Labelling Problem",ISNUMBER(SEARCH("marking",C6)),"Device Markings/Labelling Problem",ISNUMBER(SEARCH("lacerat",C6)),"Defective Device",ISNUMBER(SEARCH("cut",C6)),"Defective Device",ISNUMBER(SEARCH("leak",C6)),"Fluid/Blood Leak",ISNUMBER(SEARCH("missing",C6)),"Component Missing",ISNUMBER(SEARCH("power",C6)),"Complete Loss of Power",ISNUMBER(SEARCH("will not turn on",C6)),"Complete Loss of Power",ISNUMBER(SEARCH("won't turn on",C6)),"Complete Loss of Power",ISNUMBER(SEARCH("does not turn on",C6)),"Complete Loss of Power",ISNUMBER(SEARCH("electrical",C6)),"Electrical Power Problem",ISNUMBER(SEARCH("pressure",C6)),"Detachment of Device or Device Component",ISNUMBER(SEARCH("slip",C6)),"Detachment of Device or Device Component",ISNUMBER(SEARCH("detach",C6)),"Detachment of Device or Device Component",ISNUMBER(SEARCH("stick",C6)),"Mechanical Jam",ISNUMBER(SEARCH("jam",C6)),"Mechanical Jam",ISNUMBER(SEARCH("rigid",C6)),"Mechanical Jam",ISNUMBER(SEARCH("rust",C6)),"Corroded",ISNUMBER(SEARCH("corrod",C6)),"Corroded",ISNUMBER(SEARCH("corrosion",C6)),"Corroded",ISNUMBER(SEARCH("alignment",C6)),"Defective Device",ISNUMBER(SEARCH("adjust",C6)),"Defective Device",ISNUMBER(SEARCH("perform",C6)),"Defective Device",ISNUMBER(SEARCH("malfunction",C6)),"Defective Device",ISNUMBER(SEARCH("defect",C6)),"Defective Device",ISNUMBER(SEARCH("fail",C6)),"Defective Device",ISNUMBER(SEARCH("not work",C6)),"Defective Device",ISNUMBER(SEARCH("doesn't work",C6)),"Defective Device",TRUE,"UNKNOWN"),"UNKNOWN")))} -> UNKNOWN - colorph | F6: =IF(E6="","","No Clinical Signs, Symptoms or Conditions") -> No Clinical Signs, Symptoms or Conditions | G6: =IF(E6="","",IFERROR(VLOOKUP(E6,Codes!$L$2:$N$409,3,FALSE),"—")) -> —
A7: 2023-06-0000030 | B7: 45078 | C7: New lot is discolored- more yellow than previous lot. (Photos attached) | D7: colorph | E7: {=IF(D7<>"",IFERROR(VLOOKUP(D7,Codes!$K$2:$L$409,2,FALSE),"UNKNOWN - "&D7),IF(C7="","",IFERROR(_xlfn.IFS(ISNUMBER(SEARCH("broken button",C7)),"Break",ISNUMBER(SEARCH("broken handle",C7)),"Break",ISNUMBER(SEARCH("shipping damage",C7)),"Break",ISNUMBER(SEARCH("broken",C7)),"Break",ISNUMBER(SEARCH("crack",C7)),"Break",ISNUMBER(SEARCH("snap",C7)),"Break",ISNUMBER(SEARCH("fracture",C7)),"Break",ISNUMBER(SEARCH("bent",C7)),"Material Twisted/Bent",ISNUMBER(SEARCH("twisted",C7)),"Material Twisted/Bent",ISNUMBER(SEARCH("component separat",C7)),"Material Separation",ISNUMBER(SEARCH("separat",C7)),"Material Separation",ISNUMBER(SEARCH("connection",C7)),"Loose or Intermittent Connection",ISNUMBER(SEARCH("loose",C7)),"Loose or Intermittent Connection",ISNUMBER(SEARCH("damaged packaging",C7)),"Packaging Problem",ISNUMBER(SEARCH("packaging",C7)),"Packaging Problem",ISNUMBER(SEARCH("discoloration",C7)),"Contamination",ISNUMBER(SEARCH("tarnish",C7)),"Contamination",ISNUMBER(SEARCH("stain",C7)),"Contamination",ISNUMBER(SEARCH("foreign material",C7)),"Contamination",ISNUMBER(SEARCH("contamina",C7)),"Contamination",ISNUMBER(SEARCH("overheat",C7)),"Overheating of Device",ISNUMBER(SEARCH("excessive heat",C7)),"Overheating of Device",ISNUMBER(SEARCH("hot",C7)),"Overheating of Device",ISNUMBER(SEARCH("noise",C7)),"Noise, Audible",ISNUMBER(SEARCH("sound",C7)),"Noise, Audible",ISNUMBER(SEARCH("loud",C7)),"Noise, Audible",ISNUMBER(SEARCH("fray",C7)),"Material Frayed",ISNUMBER(SEARCH("hole",C7)),"Material Frayed",ISNUMBER(SEARCH("tear",C7)),"Material Frayed",ISNUMBER(SEARCH("worn",C7)),"Material Frayed",ISNUMBER(SEARCH("intermittent",C7)),"Difficult or Delayed Activation",ISNUMBER(SEARCH("delay",C7)),"Difficult or Delayed Activation",ISNUMBER(SEARCH("label",C7)),"Device Markings/Labelling Problem",ISNUMBER(SEARCH("marking",C7)),"Device Markings/Labelling Problem",ISNUMBER(SEARCH("lacerat",C7)),"Defective Device",ISNUMBER(SEARCH("cut",C7)),"Defective Device",ISNUMBER(SEARCH("leak",C7)),"Fluid/Blood Leak",ISNUMBER(SEARCH("missing",C7)),"Component Missing",ISNUMBER(SEARCH("power",C7)),"Complete Loss of Power",ISNUMBER(SEARCH("will not turn on",C7)),"Complete Loss of Power",ISNUMBER(SEARCH("won't turn on",C7)),"Complete Loss of Power",ISNUMBER(SEARCH("does not turn on",C7)),"Complete Loss of Power",ISNUMBER(SEARCH("electrical",C7)),"Electrical Power Problem",ISNUMBER(SEARCH("pressure",C7)),"Detachment of Device or Device Component",ISNUMBER(SEARCH("slip",C7)),"Detachment of Device or Device Component",ISNUMBER(SEARCH("detach",C7)),"Detachment of Device or Device Component",ISNUMBER(SEARCH("stick",C7)),"Mechanical Jam",ISNUMBER(SEARCH("jam",C7)),"Mechanical Jam",ISNUMBER(SEARCH("rigid",C7)),"Mechanical Jam",ISNUMBER(SEARCH("rust",C7)),"Corroded",ISNUMBER(SEARCH("corrod",C7)),"Corroded",ISNUMBER(SEARCH("corrosion",C7)),"Corroded",ISNUMBER(SEARCH("alignment",C7)),"Defective Device",ISNUMBER(SEARCH("adjust",C7)),"Defective Device",ISNUMBER(SEARCH("perform",C7)),"Defective Device",ISNUMBER(SEARCH("malfunction",C7)),"Defective Device",ISNUMBER(SEARCH("defect",C7)),"Defective Device",ISNUMBER(SEARCH("fail",C7)),"Defective Device",ISNUMBER(SEARCH("not work",C7)),"Defective Device",ISNUMBER(SEARCH("doesn't work",C7)),"Defective Device",TRUE,"UNKNOWN"),"UNKNOWN")))} -> UNKNOWN - colorph | F7: =IF(E7="","","No Clinical Signs, Symptoms or Conditions") -> No Clinical Signs, Symptoms or Conditions | G7: =IF(E7="","",IFERROR(VLOOKUP(E7,Codes!$L$2:$N$409,3,FALSE),"—")) -> —
A8: 2023-06-0000116 | B8: 45083 | C8: Color of some bottles is yellow. I have attached data logger details. (Photo attached) | D8: colorph | E8: {=IF(D8<>"",IFERROR(VLOOKUP(D8,Codes!$K$2:$L$409,2,FALSE),"UNKNOWN - "&D8),IF(C8="","",IFERROR(_xlfn.IFS(ISNUMBER(SEARCH("broken button",C8)),"Break",ISNUMBER(SEARCH("broken handle",C8)),"Break",ISNUMBER(SEARCH("shipping damage",C8)),"Break",ISNUMBER(SEARCH("broken",C8)),"Break",ISNUMBER(SEARCH("crack",C8)),"Break",ISNUMBER(SEARCH("snap",C8)),"Break",ISNUMBER(SEARCH("fracture",C8)),"Break",ISNUMBER(SEARCH("bent",C8)),"Material Twisted/Bent",ISNUMBER(SEARCH("twisted",C8)),"Material Twisted/Bent",ISNUMBER(SEARCH("component separat",C8)),"Material Separation",ISNUMBER(SEARCH("separat",C8)),"Material Separation",ISNUMBER(SEARCH("connection",C8)),"Loose or Intermittent Connection",ISNUMBER(SEARCH("loose",C8)),"Loose or Intermittent Connection",ISNUMBER(SEARCH("damaged packaging",C8)),"Packaging Problem",ISNUMBER(SEARCH("packaging",C8)),"Packaging Problem",ISNUMBER(SEARCH("discoloration",C8)),"Contamination",ISNUMBER(SEARCH("tarnish",C8)),"Contamination",ISNUMBER(SEARCH("stain",C8)),"Contamination",ISNUMBER(SEARCH("foreign material",C8)),"Contamination",ISNUMBER(SEARCH("contamina",C8)),"Contamination",ISNUMBER(SEARCH("overheat",C8)),"Overheating of Device",ISNUMBER(SEARCH("excessive heat",C8)),"Overheating of Device",ISNUMBER(SEARCH("hot",C8)),"Overheating of Device",ISNUMBER(SEARCH("noise",C8)),"Noise, Audible",ISNUMBER(SEARCH("sound",C8)),"Noise, Audible",ISNUMBER(SEARCH("loud",C8)),"Noise, Audible",ISNUMBER(SEARCH("fray",C8)),"Material Frayed",ISNUMBER(SEARCH("hole",C8)),"Material Frayed",ISNUMBER(SEARCH("tear",C8)),"Material Frayed",ISNUMBER(SEARCH("worn",C8)),"Material Frayed",ISNUMBER(SEARCH("intermittent",C8)),"Difficult or Delayed Activation",ISNUMBER(SEARCH("delay",C8)),"Difficult or Delayed Activation",ISNUMBER(SEARCH("label",C8)),"Device Markings/Labelling Problem",ISNUMBER(SEARCH("marking",C8)),"Device Markings/Labelling Problem",ISNUMBER(SEARCH("lacerat",C8)),"Defective Device",ISNUMBER(SEARCH("cut",C8)),"Defective Device",ISNUMBER(SEARCH("leak",C8)),"Fluid/Blood Leak",ISNUMBER(SEARCH("missing",C8)),"Component Missing",ISNUMBER(SEARCH("power",C8)),"Complete Loss of Power",ISNUMBER(SEARCH("will not turn on",C8)),"Complete Loss of Power",ISNUMBER(SEARCH("won't turn on",C8)),"Complete Loss of Power",ISNUMBER(SEARCH("does not turn on",C8)),"Complete Loss of Power",ISNUMBER(SEARCH("electrical",C8)),"Electrical Power Problem",ISNUMBER(SEARCH("pressure",C8)),"Detachment of Device or Device Component",ISNUMBER(SEARCH("slip",C8)),"Detachment of Device or Device Component",ISNUMBER(SEARCH("detach",C8)),"Detachment of Device or Device Component",ISNUMBER(SEARCH("stick",C8)),"Mechanical Jam",ISNUMBER(SEARCH("jam",C8)),"Mechanical Jam",ISNUMBER(SEARCH("rigid",C8)),"Mechanical Jam",ISNUMBER(SEARCH("rust",C8)),"Corroded",ISNUMBER(SEARCH("corrod",C8)),"Corroded",ISNUMBER(SEARCH("corrosion",C8)),"Corroded",ISNUMBER(SEARCH("alignment",C8)),"Defective Device",ISNUMBER(SEARCH("adjust",C8)),"Defective Device",ISNUMBER(SEARCH("perform",C8)),"Defective Device",ISNUMBER(SEARCH("malfunction",C8)),"Defective Device",ISNUMBER(SEARCH("defect",C8)),"Defective Device",ISNUMBER(SEARCH("fail",C8)),"Defective Device",ISNUMBER(SEARCH("not work",C8)),"Defective Device",ISNUMBER(SEARCH("doesn't work",C8)),"Defective Device",TRUE,"UNKNOWN"),"UNKNOWN")))} -> UNKNOWN - colorph | F8: =IF(E8="","","No Clinical Signs, Symptoms or Conditions") -> No Clinical Signs, Symptoms or Conditions | G8: =IF(E8="","",IFERROR(VLOOKUP(E8,Codes!$L$2:$N$409,3,FALSE),"—")) -> —
A9: 2023-06-0000121 | B9: 45083 | C9: discoloration of media product. will not use. Customer does not trust the media and current LGQC procedures. customer extremely concerned about media QC. does not trust LG media at this time. Very upset with CR manufacturing. (Photo attached)_x000D_ _x000D_ Patient, Gamete, Embryo, or End User Involvement? no | D9: colorph | E9: {=IF(D9<>"",IFERROR(VLOOKUP(D9,Codes!$K$2:$L$409,2,FALSE),"UNKNOWN - "&D9),IF(C9="","",IFERROR(_xlfn.IFS(ISNUMBER(SEARCH("broken button",C9)),"Break",ISNUMBER(SEARCH("broken handle",C9)),"Break",ISNUMBER(SEARCH("shipping damage",C9)),"Break",ISNUMBER(SEARCH("broken",C9)),"Break",ISNUMBER(SEARCH("crack",C9)),"Break",ISNUMBER(SEARCH("snap",C9)),"Break",ISNUMBER(SEARCH("fracture",C9)),"Break",ISNUMBER(SEARCH("bent",C9)),"Material Twisted/Bent",ISNUMBER(SEARCH("twisted",C9)),"Material Twisted/Bent",ISNUMBER(SEARCH("component separat",C9)),"Material Separation",ISNUMBER(SEARCH("separat",C9)),"Material Separation",ISNUMBER(SEARCH("connection",C9)),"Loose or Intermittent Connection",ISNUMBER(SEARCH("loose",C9)),"Loose or Intermittent Connection",ISNUMBER(SEARCH("damaged packaging",C9)),"Packaging Problem",ISNUMBER(SEARCH("packaging",C9)),"Packaging Problem",ISNUMBER(SEARCH("discoloration",C9)),"Contamination",ISNUMBER(SEARCH("tarnish",C9)),"Contamination",ISNUMBER(SEARCH("stain",C9)),"Contamination",ISNUMBER(SEARCH("foreign material",C9)),"Contamination",ISNUMBER(SEARCH("contamina",C9)),"Contamination",ISNUMBER(SEARCH("overheat",C9)),"Overheating of Device",ISNUMBER(SEARCH("excessive heat",C9)),"Overheating of Device",ISNUMBER(SEARCH("hot",C9)),"Overheating of Device",ISNUMBER(SEARCH("noise",C9)),"Noise, Audible",ISNUMBER(SEARCH("sound",C9)),"Noise, Audible",ISNUMBER(SEARCH("loud",C9)),"Noise, Audible",ISNUMBER(SEARCH("fray",C9)),"Material Frayed",ISNUMBER(SEARCH("hole",C9)),"Material Frayed",ISNUMBER(SEARCH("tear",C9)),"Material Frayed",ISNUMBER(SEARCH("worn",C9)),"Material Frayed",ISNUMBER(SEARCH("intermittent",C9)),"Difficult or Delayed Activation",ISNUMBER(SEARCH("delay",C9)),"Difficult or Delayed Activation",ISNUMBER(SEARCH("label",C9)),"Device Markings/Labelling Problem",ISNUMBER(SEARCH("marking",C9)),"Device Markings/Labelling Problem",ISNUMBER(SEARCH("lacerat",C9)),"Defective Device",ISNUMBER(SEARCH("cut",C9)),"Defective Device",ISNUMBER(SEARCH("leak",C9)),"Fluid/Blood Leak",ISNUMBER(SEARCH("missing",C9)),"Component Missing",ISNUMBER(SEARCH("power",C9)),"Complete Loss of Power",ISNUMBER(SEARCH("will not turn on",C9)),"Complete Loss of Power",ISNUMBER(SEARCH("won't turn on",C9)),"Complete Loss of Power",ISNUMBER(SEARCH("does not turn on",C9)),"Complete Loss of Power",ISNUMBER(SEARCH("electrical",C9)),"Electrical Power Problem",ISNUMBER(SEARCH("pressure",C9)),"Detachment of Device or Device Component",ISNUMBER(SEARCH("slip",C9)),"Detachment of Device or Device Component",ISNUMBER(SEARCH("detach",C9)),"Detachment of Device or Device Component",ISNUMBER(SEARCH("stick",C9)),"Mechanical Jam",ISNUMBER(SEARCH("jam",C9)),"Mechanical Jam",ISNUMBER(SEARCH("rigid",C9)),"Mechanical Jam",ISNUMBER(SEARCH("rust",C9)),"Corroded",ISNUMBER(SEARCH("corrod",C9)),"Corroded",ISNUMBER(SEARCH("corrosion",C9)),"Corroded",ISNUMBER(SEARCH("alignment",C9)),"Defective Device",ISNUMBER(SEARCH("adjust",C9)),"Defective Device",ISNUMBER(SEARCH("perform",C9)),"Defective Device",ISNUMBER(SEARCH("malfunction",C9)),"Defective Device",ISNUMBER(SEARCH("defect",C9)),"Defective Device",ISNUMBER(SEARCH("fail",C9)),"Defective Device",ISNUMBER(SEARCH("not work",C9)),"Defective Device",ISNUMBER(SEARCH("doesn't work",C9)),"Defective Device",TRUE,"UNKNOWN"),"UNKNOWN")))} -> UNKNOWN - colorph | F9: =IF(E9="","","No Clinical Signs, Symptoms or Conditions") -> No Clinical Signs, Symptoms or Conditions | G9: =IF(E9="","",IFERROR(VLOOKUP(E9,Codes!$L$2:$N$409,3,FALSE),"—")) -> —
A10: 2023-06-0000281 | B10: 45088 | C10: Discoloration_x000D_ _x000D_ This lab director has had multiple media issues and both of her labs (Stanford being the other), and she is very vocal in the IVF community about the media issues and Cooper not giving her answers. | D10: colorph | E10: {=IF(D10<>"",IFERROR(VLOOKUP(D10,Codes!$K$2:$L$409,2,FALSE),"UNKNOWN - "&D10),IF(C10="","",IFERROR(_xlfn.IFS(ISNUMBER(SEARCH("broken button",C10)),"Break",ISNUMBER(SEARCH("broken handle",C10)),"Break",ISNUMBER(SEARCH("shipping damage",C10)),"Break",ISNUMBER(SEARCH("broken",C10)),"Break",ISNUMBER(SEARCH("crack",C10)),"Break",ISNUMBER(SEARCH("snap",C10)),"Break",ISNUMBER(SEARCH("fracture",C10)),"Break",ISNUMBER(SEARCH("bent",C10)),"Material Twisted/Bent",ISNUMBER(SEARCH("twisted",C10)),"Material Twisted/Bent",ISNUMBER(SEARCH("component separat",C10)),"Material Separation",ISNUMBER(SEARCH("separat",C10)),"Material Separation",ISNUMBER(SEARCH("connection",C10)),"Loose or Intermittent Connection",ISNUMBER(SEARCH("loose",C10)),"Loose or Intermittent Connection",ISNUMBER(SEARCH("damaged packaging",C10)),"Packaging Problem",ISNUMBER(SEARCH("packaging",C10)),"Packaging Problem",ISNUMBER(SEARCH("discoloration",C10)),"Contamination",ISNUMBER(SEARCH("tarnish",C10)),"Contamination",ISNUMBER(SEARCH("stain",C10)),"Contamination",ISNUMBER(SEARCH("foreign material",C10)),"Contamination",ISNUMBER(SEARCH("contamina",C10)),"Contamination",ISNUMBER(SEARCH("overheat",C10)),"Overheating of Device",ISNUMBER(SEARCH("excessive heat",C10)),"Overheating of Device",ISNUMBER(SEARCH("hot",C10)),"Overheating of Device",ISNUMBER(SEARCH("noise",C10)),"Noise, Audible",ISNUMBER(SEARCH("sound",C10)),"Noise, Audible",ISNUMBER(SEARCH("loud",C10)),"Noise, Audible",ISNUMBER(SEARCH("fray",C10)),"Material Frayed",ISNUMBER(SEARCH("hole",C10)),"Material Frayed",ISNUMBER(SEARCH("tear",C10)),"Material Frayed",ISNUMBER(SEARCH("worn",C10)),"Material Frayed",ISNUMBER(SEARCH("intermittent",C10)),"Difficult or Delayed Activation",ISNUMBER(SEARCH("delay",C10)),"Difficult or Delayed Activation",ISNUMBER(SEARCH("label",C10)),"Device Markings/Labelling Problem",ISNUMBER(SEARCH("marking",C10)),"Device Markings/Labelling Problem",ISNUMBER(SEARCH("lacerat",C10)),"Defective Device",ISNUMBER(SEARCH("cut",C10)),"Defective Device",ISNUMBER(SEARCH("leak",C10)),"Fluid/Blood Leak",ISNUMBER(SEARCH("missing",C10)),"Component Missing",ISNUMBER(SEARCH("power",C10)),"Complete Loss of Power",ISNUMBER(SEARCH("will not turn on",C10)),"Complete Loss of Power",ISNUMBER(SEARCH("won't turn on",C10)),"Complete Loss of Power",ISNUMBER(SEARCH("does not turn on",C10)),"Complete Loss of Power",ISNUMBER(SEARCH("electrical",C10)),"Electrical Power Problem",ISNUMBER(SEARCH("pressure",C10)),"Detachment of Device or Device Component",ISNUMBER(SEARCH("slip",C10)),"Detachment of Device or Device Component",ISNUMBER(SEARCH("detach",C10)),"Detachment of Device or Device Component",ISNUMBER(SEARCH("stick",C10)),"Mechanical Jam",ISNUMBER(SEARCH("jam",C10)),"Mechanical Jam",ISNUMBER(SEARCH("rigid",C10)),"Mechanical Jam",ISNUMBER(SEARCH("rust",C10)),"Corroded",ISNUMBER(SEARCH("corrod",C10)),"Corroded",ISNUMBER(SEARCH("corrosion",C10)),"Corroded",ISNUMBER(SEARCH("alignment",C10)),"Defective Device",ISNUMBER(SEARCH("adjust",C10)),"Defective Device",ISNUMBER(SEARCH("perform",C10)),"Defective Device",ISNUMBER(SEARCH("malfunction",C10)),"Defective Device",ISNUMBER(SEARCH("defect",C10)),"Defective Device",ISNUMBER(SEARCH("fail",C10)),"Defective Device",ISNUMBER(SEARCH("not work",C10)),"Defective Device",ISNUMBER(SEARCH("doesn't work",C10)),"Defective Device",TRUE,"UNKNOWN"),"UNKNOWN")))} -> UNKNOWN - colorph | F10: =IF(E10="","","No Clinical Signs, Symptoms or Conditions") -> No Clinical Signs, Symptoms or Conditions | G10: =IF(E10="","",IFERROR(VLOOKUP(E10,Codes!$L$2:$N$409,3,FALSE),"—")) -> —
A11: 2023-06-0000348 | B11: 45091 | C11: The cultured embryos are dark in color and coarse particles, the embryo cyst formation rate is significantly lower than our normal level, the color of the medium and the pH value has changed from the appearance. (Photo attached) | D11: colorph | E11: {=IF(D11<>"",IFERROR(VLOOKUP(D11,Codes!$K$2:$L$409,2,FALSE),"UNKNOWN - "&D11),IF(C11="","",IFERROR(_xlfn.IFS(ISNUMBER(SEARCH("broken button",C11)),"Break",ISNUMBER(SEARCH("broken handle",C11)),"Break",ISNUMBER(SEARCH("shipping damage",C11)),"Break",ISNUMBER(SEARCH("broken",C11)),"Break",ISNUMBER(SEARCH("crack",C11)),"Break",ISNUMBER(SEARCH("snap",C11)),"Break",ISNUMBER(SEARCH("fracture",C11)),"Break",ISNUMBER(SEARCH("bent",C11)),"Material Twisted/Bent",ISNUMBER(SEARCH("twisted",C11)),"Material Twisted/Bent",ISNUMBER(SEARCH("component separat",C11)),"Material Separation",ISNUMBER(SEARCH("separat",C11)),"Material Separation",ISNUMBER(SEARCH("connection",C11)),"Loose or Intermittent Connection",ISNUMBER(SEARCH("loose",C11)),"Loose or Intermittent Connection",ISNUMBER(SEARCH("damaged packaging",C11)),"Packaging Problem",ISNUMBER(SEARCH("packaging",C11)),"Packaging Problem",ISNUMBER(SEARCH("discoloration",C11)),"Contamination",ISNUMBER(SEARCH("tarnish",C11)),"Contamination",ISNUMBER(SEARCH("stain",C11)),"Contamination",ISNUMBER(SEARCH("foreign material",C11)),"Contamination",ISNUMBER(SEARCH("contamina",C11)),"Contamination",ISNUMBER(SEARCH("overheat",C11)),"Overheating of Device",ISNUMBER(SEARCH("excessive heat",C11)),"Overheating of Device",ISNUMBER(SEARCH("hot",C11)),"Overheating of Device",ISNUMBER(SEARCH("noise",C11)),"Noise, Audible",ISNUMBER(SEARCH("sound",C11)),"Noise, Audible",ISNUMBER(SEARCH("loud",C11)),"Noise, Audible",ISNUMBER(SEARCH("fray",C11)),"Material Frayed",ISNUMBER(SEARCH("hole",C11)),"Material Frayed",ISNUMBER(SEARCH("tear",C11)),"Material Frayed",ISNUMBER(SEARCH("worn",C11)),"Material Frayed",ISNUMBER(SEARCH("intermittent",C11)),"Difficult or Delayed Activation",ISNUMBER(SEARCH("delay",C11)),"Difficult or Delayed Activation",ISNUMBER(SEARCH("label",C11)),"Device Markings/Labelling Problem",ISNUMBER(SEARCH("marking",C11)),"Device Markings/Labelling Problem",ISNUMBER(SEARCH("lacerat",C11)),"Defective Device",ISNUMBER(SEARCH("cut",C11)),"Defective Device",ISNUMBER(SEARCH("leak",C11)),"Fluid/Blood Leak",ISNUMBER(SEARCH("missing",C11)),"Component Missing",ISNUMBER(SEARCH("power",C11)),"Complete Loss of Power",ISNUMBER(SEARCH("will not turn on",C11)),"Complete Loss of Power",ISNUMBER(SEARCH("won't turn on",C11)),"Complete Loss of Power",ISNUMBER(SEARCH("does not turn on",C11)),"Complete Loss of Power",ISNUMBER(SEARCH("electrical",C11)),"Electrical Power Problem",ISNUMBER(SEARCH("pressure",C11)),"Detachment of Device or Device Component",ISNUMBER(SEARCH("slip",C11)),"Detachment of Device or Device Component",ISNUMBER(SEARCH("detach",C11)),"Detachment of Device or Device Component",ISNUMBER(SEARCH("stick",C11)),"Mechanical Jam",ISNUMBER(SEARCH("jam",C11)),"Mechanical Jam",ISNUMBER(SEARCH("rigid",C11)),"Mechanical Jam",ISNUMBER(SEARCH("rust",C11)),"Corroded",ISNUMBER(SEARCH("corrod",C11)),"Corroded",ISNUMBER(SEARCH("corrosion",C11)),"Corroded",ISNUMBER(SEARCH("alignment",C11)),"Defective Device",ISNUMBER(SEARCH("adjust",C11)),"Defective Device",ISNUMBER(SEARCH("perform",C11)),"Defective Device",ISNUMBER(SEARCH("malfunction",C11)),"Defective Device",ISNUMBER(SEARCH("defect",C11)),"Defective Device",ISNUMBER(SEARCH("fail",C11)),"Defective Device",ISNUMBER(SEARCH("not work",C11)),"Defective Device",ISNUMBER(SEARCH("doesn't work",C11)),"Defective Device",TRUE,"UNKNOWN"),"UNKNOWN")))} -> UNKNOWN - colorph | F11: =IF(E11="","","No Clinical Signs, Symptoms or Conditions") -> No Clinical Signs, Symptoms or Conditions | G11: =IF(E11="","",IFERROR(VLOOKUP(E11,Codes!$L$2:$N$409,3,FALSE),"—")) -> —
A12: 2023-06-0000391 | B12: 45093 | C12: Product arrived with the color off. It is light pink/peach and with all the media issues lately, customer does not trust to use this. _x000D_ _x000D_ Patient, Gamete, Embryo, or End User Involvement? No | D12: colorph | E12: {=IF(D12<>"",IFERROR(VLOOKUP(D12,Codes!$K$2:$L$409,2,FALSE),"UNKNOWN - "&D12),IF(C12="","",IFERROR(_xlfn.IFS(ISNUMBER(SEARCH("broken button",C12)),"Break",ISNUMBER(SEARCH("broken handle",C12)),"Break",ISNUMBER(SEARCH("shipping damage",C12)),"Break",ISNUMBER(SEARCH("broken",C12)),"Break",ISNUMBER(SEARCH("crack",C12)),"Break",ISNUMBER(SEARCH("snap",C12)),"Break",ISNUMBER(SEARCH("fracture",C12)),"Break",ISNUMBER(SEARCH("bent",C12)),"Material Twisted/Bent",ISNUMBER(SEARCH("twisted",C12)),"Material Twisted/Bent",ISNUMBER(SEARCH("component separat",C12)),"Material Separation",ISNUMBER(SEARCH("separat",C12)),"Material Separation",ISNUMBER(SEARCH("connection",C12)),"Loose or Intermittent Connection",ISNUMBER(SEARCH("loose",C12)),"Loose or Intermittent Connection",ISNUMBER(SEARCH("damaged packaging",C12)),"Packaging Problem",ISNUMBER(SEARCH("packaging",C12)),"Packaging Problem",ISNUMBER(SEARCH("discoloration",C12)),"Contamination",ISNUMBER(SEARCH("tarnish",C12)),"Contamination",ISNUMBER(SEARCH("stain",C12)),"Contamination",ISNUMBER(SEARCH("foreign material",C12)),"Contamination",ISNUMBER(SEARCH("contamina",C12)),"Contamination",ISNUMBER(SEARCH("overheat",C12)),"Overheating of Device",ISNUMBER(SEARCH("excessive heat",C12)),"Overheating of Device",ISNUMBER(SEARCH("hot",C12)),"Overheating of Device",ISNUMBER(SEARCH("noise",C12)),"Noise, Audible",ISNUMBER(SEARCH("sound",C12)),"Noise, Audible",ISNUMBER(SEARCH("loud",C12)),"Noise, Audible",ISNUMBER(SEARCH("fray",C12)),"Material Frayed",ISNUMBER(SEARCH("hole",C12)),"Material Frayed",ISNUMBER(SEARCH("tear",C12)),"Material Frayed",ISNUMBER(SEARCH("worn",C12)),"Material Frayed",ISNUMBER(SEARCH("intermittent",C12)),"Difficult or Delayed Activation",ISNUMBER(SEARCH("delay",C12)),"Difficult or Delayed Activation",ISNUMBER(SEARCH("label",C12)),"Device Markings/Labelling Problem",ISNUMBER(SEARCH("marking",C12)),"Device Markings/Labelling Problem",ISNUMBER(SEARCH("lacerat",C12)),"Defective Device",ISNUMBER(SEARCH("cut",C12)),"Defective Device",ISNUMBER(SEARCH("leak",C12)),"Fluid/Blood Leak",ISNUMBER(SEARCH("missing",C12)),"Component Missing",ISNUMBER(SEARCH("power",C12)),"Complete Loss of Power",ISNUMBER(SEARCH("will not turn on",C12)),"Complete Loss of Power",ISNUMBER(SEARCH("won't turn on",C12)),"Complete Loss of Power",ISNUMBER(SEARCH("does not turn on",C12)),"Complete Loss of Power",ISNUMBER(SEARCH("electrical",C12)),"Electrical Power Problem",ISNUMBER(SEARCH("pressure",C12)),"Detachment of Device or Device Component",ISNUMBER(SEARCH("slip",C12)),"Detachment of Device or Device Component",ISNUMBER(SEARCH("detach",C12)),"Detachment of Device or Device Component",ISNUMBER(SEARCH("stick",C12)),"Mechanical Jam",ISNUMBER(SEARCH("jam",C12)),"Mechanical Jam",ISNUMBER(SEARCH("rigid",C12)),"Mechanical Jam",ISNUMBER(SEARCH("rust",C12)),"Corroded",ISNUMBER(SEARCH("corrod",C12)),"Corroded",ISNUMBER(SEARCH("corrosion",C12)),"Corroded",ISNUMBER(SEARCH("alignment",C12)),"Defective Device",ISNUMBER(SEARCH("adjust",C12)),"Defective Device",ISNUMBER(SEARCH("perform",C12)),"Defective Device",ISNUMBER(SEARCH("malfunction",C12)),"Defective Device",ISNUMBER(SEARCH("defect",C12)),"Defective Device",ISNUMBER(SEARCH("fail",C12)),"Defective Device",ISNUMBER(SEARCH("not work",C12)),"Defective Device",ISNUMBER(SEARCH("doesn't work",C12)),"Defective Device",TRUE,"UNKNOWN"),"UNKNOWN")))} -> UNKNOWN - colorph | F12: =IF(E12="","","No Clinical Signs, Symptoms or Conditions") -> No Clinical Signs, Symptoms or Conditions | G12: =IF(E12="","",IFERROR(VLOOKUP(E12,Codes!$L$2:$N$409,3,FALSE),"—")) -> —
A13: 2023-12-0000241 | B13: 45265 | C13: Customer is reporting lower than normal blast rates. The media was used between 10/7- 10/15. _x000D_ _x000D_ Follow up response:_x000D_ We are not requesting credit, we’re requesting information of if anyone else reported anything related to these lots of medium, or if you find an any problems during your investigation | D13: performance | E13: {=IF(D13<>"",IFERROR(VLOOKUP(D13,Codes!$K$2:$L$409,2,FALSE),"UNKNOWN - "&D13),IF(C13="","",IFERROR(_xlfn.IFS(ISNUMBER(SEARCH("broken button",C13)),"Break",ISNUMBER(SEARCH("broken handle",C13)),"Break",ISNUMBER(SEARCH("shipping damage",C13)),"Break",ISNUMBER(SEARCH("broken",C13)),"Break",ISNUMBER(SEARCH("crack",C13)),"Break",ISNUMBER(SEARCH("snap",C13)),"Break",ISNUMBER(SEARCH("fracture",C13)),"Break",ISNUMBER(SEARCH("bent",C13)),"Material Twisted/Bent",ISNUMBER(SEARCH("twisted",C13)),"Material Twisted/Bent",ISNUMBER(SEARCH("component separat",C13)),"Material Separation",ISNUMBER(SEARCH("separat",C13)),"Material Separation",ISNUMBER(SEARCH("connection",C13)),"Loose or Intermittent Connection",ISNUMBER(SEARCH("loose",C13)),"Loose or Intermittent Connection",ISNUMBER(SEARCH("damaged packaging",C13)),"Packaging Problem",ISNUMBER(SEARCH("packaging",C13)),"Packaging Problem",ISNUMBER(SEARCH("discoloration",C13)),"Contamination",ISNUMBER(SEARCH("tarnish",C13)),"Contamination",ISNUMBER(SEARCH("stain",C13)),"Contamination",ISNUMBER(SEARCH("foreign material",C13)),"Contamination",ISNUMBER(SEARCH("contamina",C13)),"Contamination",ISNUMBER(SEARCH("overheat",C13)),"Overheating of Device",ISNUMBER(SEARCH("excessive heat",C13)),"Overheating of Device",ISNUMBER(SEARCH("hot",C13)),"Overheating of Device",ISNUMBER(SEARCH("noise",C13)),"Noise, Audible",ISNUMBER(SEARCH("sound",C13)),"Noise, Audible",ISNUMBER(SEARCH("loud",C13)),"Noise, Audible",ISNUMBER(SEARCH("fray",C13)),"Material Frayed",ISNUMBER(SEARCH("hole",C13)),"Material Frayed",ISNUMBER(SEARCH("tear",C13)),"Material Frayed",ISNUMBER(SEARCH("worn",C13)),"Material Frayed",ISNUMBER(SEARCH("intermittent",C13)),"Difficult or Delayed Activation",ISNUMBER(SEARCH("delay",C13)),"Difficult or Delayed Activation",ISNUMBER(SEARCH("label",C13)),"Device Markings/Labelling Problem",ISNUMBER(SEARCH("marking",C13)),"Device Markings/Labelling Problem",ISNUMBER(SEARCH("lacerat",C13)),"Defective Device",ISNUMBER(SEARCH("cut",C13)),"Defective Device",ISNUMBER(SEARCH("leak",C13)),"Fluid/Blood Leak",ISNUMBER(SEARCH("missing",C13)),"Component Missing",ISNUMBER(SEARCH("power",C13)),"Complete Loss of Power",ISNUMBER(SEARCH("will not turn on",C13)),"Complete Loss of Power",ISNUMBER(SEARCH("won't turn on",C13)),"Complete Loss of Power",ISNUMBER(SEARCH("does not turn on",C13)),"Complete Loss of Power",ISNUMBER(SEARCH("electrical",C13)),"Electrical Power Problem",ISNUMBER(SEARCH("pressure",C13)),"Detachment of Device or Device Component",ISNUMBER(SEARCH("slip",C13)),"Detachment of Device or Device Component",ISNUMBER(SEARCH("detach",C13)),"Detachment of Device or Device Component",ISNUMBER(SEARCH("stick",C13)),"Mechanical Jam",ISNUMBER(SEARCH("jam",C13)),"Mechanical Jam",ISNUMBER(SEARCH("rigid",C13)),"Mechanical Jam",ISNUMBER(SEARCH("rust",C13)),"Corroded",ISNUMBER(SEARCH("corrod",C13)),"Corroded",ISNUMBER(SEARCH("corrosion",C13)),"Corroded",ISNUMBER(SEARCH("alignment",C13)),"Defective Device",ISNUMBER(SEARCH("adjust",C13)),"Defective Device",ISNUMBER(SEARCH("perform",C13)),"Defective Device",ISNUMBER(SEARCH("malfunction",C13)),"Defective Device",ISNUMBER(SEARCH("defect",C13)),"Defective Device",ISNUMBER(SEARCH("fail",C13)),"Defective Device",ISNUMBER(SEARCH("not work",C13)),"Defective Device",ISNUMBER(SEARCH("doesn't work",C13)),"Defective Device",TRUE,"UNKNOWN"),"UNKNOWN")))} -> Defective Device | F13: =IF(E13="","","No Clinical Signs, Symptoms or Conditions") -> No Clinical Signs, Symptoms or Conditions | G13: =IF(E13="","",IFERROR(VLOOKUP(E13,Codes!$L$2:$N$409,3,FALSE),"—")) -> A0203
... A21: 2025-10-0000274 | B21: 45939 | C21: customer standing order arrived warm, _x000D_ shipped on 10/6 and arrived on 10/8 - customer sayd temp was at 9 degrees and ice pack melted._x000D_ _x000D_ Invoice: SO5500000480485 | D21: arrivedwarm | E21: {=IF(D21<>"",IFERROR(VLOOKUP(D21,Codes!$K$2:$L$409,2,FALSE),"UNKNOWN - "&D21),IF(C21="","",IFERROR(_xlfn.IFS(ISNUMBER(SEARCH("broken button",C21)),"Break",ISNUMBER(SEARCH("broken handle",C21)),"Break",ISNUMBER(SEARCH("shipping damage",C21)),"Break",ISNUMBER(SEARCH("broken",C21)),"Break",ISNUMBER(SEARCH("crack",C21)),"Break",ISNUMBER(SEARCH("snap",C21)),"Break",ISNUMBER(SEARCH("fracture",C21)),"Break",ISNUMBER(SEARCH("bent",C21)),"Material Twisted/Bent",ISNUMBER(SEARCH("twisted",C21)),"Material Twisted/Bent",ISNUMBER(SEARCH("component separat",C21)),"Material Separation",ISNUMBER(SEARCH("separat",C21)),"Material Separation",ISNUMBER(SEARCH("connection",C21)),"Loose or Intermittent Connection",ISNUMBER(SEARCH("loose",C21)),"Loose or Intermittent Connection",ISNUMBER(SEARCH("damaged packaging",C21)),"Packaging Problem",ISNUMBER(SEARCH("packaging",C21)),"Packaging Problem",ISNUMBER(SEARCH("discoloration",C21)),"Contamination",ISNUMBER(SEARCH("tarnish",C21)),"Contamination",ISNUMBER(SEARCH("stain",C21)),"Contamination",ISNUMBER(SEARCH("foreign material",C21)),"Contamination",ISNUMBER(SEARCH("contamina",C21)),"Contamination",ISNUMBER(SEARCH("overheat",C21)),"Overheating of Device",ISNUMBER(SEARCH("excessive heat",C21)),"Overheating of Device",ISNUMBER(SEARCH("hot",C21)),"Overheating of Device",ISNUMBER(SEARCH("noise",C21)),"Noise, Audible",ISNUMBER(SEARCH("sound",C21)),"Noise, Audible",ISNUMBER(SEARCH("loud",C21)),"Noise, Audible",ISNUMBER(SEARCH("fray",C21)),"Material Frayed",ISNUMBER(SEARCH("hole",C21)),"Material Frayed",ISNUMBER(SEARCH("tear",C21)),"Material Frayed",ISNUMBER(SEARCH("worn",C21)),"Material Frayed",ISNUMBER(SEARCH("intermittent",C21)),"Difficult or Delayed Activation",ISNUMBER(SEARCH("delay",C21)),"Difficult or Delayed Activation",ISNUMBER(SEARCH("label",C21)),"Device Markings/Labelling Problem",ISNUMBER(SEARCH("marking",C21)),"Device Markings/Labelling Problem",ISNUMBER(SEARCH("lacerat",C21)),"Defective Device",ISNUMBER(SEARCH("cut",C21)),"Defective Device",ISNUMBER(SEARCH("leak",C21)),"Fluid/Blood Leak",ISNUMBER(SEARCH("missing",C21)),"Component Missing",ISNUMBER(SEARCH("power",C21)),"Complete Loss of Power",ISNUMBER(SEARCH("will not turn on",C21)),"Complete Loss of Power",ISNUMBER(SEARCH("won't turn on",C21)),"Complete Loss of Power",ISNUMBER(SEARCH("does not turn on",C21)),"Complete Loss of Power",ISNUMBER(SEARCH("electrical",C21)),"Electrical Power Problem",ISNUMBER(SEARCH("pressure",C21)),"Detachment of Device or Device Component",ISNUMBER(SEARCH("slip",C21)),"Detachment of Device or Device Component",ISNUMBER(SEARCH("detach",C21)),"Detachment of Device or Device Component",ISNUMBER(SEARCH("stick",C21)),"Mechanical Jam",ISNUMBER(SEARCH("jam",C21)),"Mechanical Jam",ISNUMBER(SEARCH("rigid",C21)),"Mechanical Jam",ISNUMBER(SEARCH("rust",C21)),"Corroded",ISNUMBER(SEARCH("corrod",C21)),"Corroded",ISNUMBER(SEARCH("corrosion",C21)),"Corroded",ISNUMBER(SEARCH("alignment",C21)),"Defective Device",ISNUMBER(SEARCH("adjust",C21)),"Defective Device",ISNUMBER(SEARCH("perform",C21)),"Defective Device",ISNUMBER(SEARCH("malfunction",C21)),"Defective Device",ISNUMBER(SEARCH("defect",C21)),"Defective Device",ISNUMBER(SEARCH("fail",C21)),"Defective Device",ISNUMBER(SEARCH("not work",C21)),"Defective Device",ISNUMBER(SEARCH("doesn't work",C21)),"Defective Device",TRUE,"UNKNOWN"),"UNKNOWN")))} -> UNKNOWN - arrivedwarm | F21: =IF(E21="","","No Clinical Signs, Symptoms or Conditions") -> No Clinical Signs, Symptoms or Conditions | G21: =IF(E21="","",IFERROR(VLOOKUP(E21,Codes!$L$2:$N$409,3,FALSE),"—")) -> —
E22: {=IF(D22<>"",IFERROR(VLOOKUP(D22,Codes!$K$2:$L$409,2,FALSE),"UNKNOWN - "&D22),IF(C22="","",IFERROR(_xlfn.IFS(ISNUMBER(SEARCH("broken button",C22)),"Break",ISNUMBER(SEARCH("broken handle",C22)),"Break",ISNUMBER(SEARCH("shipping damage",C22)),"Break",ISNUMBER(SEARCH("broken",C22)),"Break",ISNUMBER(SEARCH("crack",C22)),"Break",ISNUMBER(SEARCH("snap",C22)),"Break",ISNUMBER(SEARCH("fracture",C22)),"Break",ISNUMBER(SEARCH("bent",C22)),"Material Twisted/Bent",ISNUMBER(SEARCH("twisted",C22)),"Material Twisted/Bent",ISNUMBER(SEARCH("component separat",C22)),"Material Separation",ISNUMBER(SEARCH("separat",C22)),"Material Separation",ISNUMBER(SEARCH("connection",C22)),"Loose or Intermittent Connection",ISNUMBER(SEARCH("loose",C22)),"Loose or Intermittent Connection",ISNUMBER(SEARCH("damaged packaging",C22)),"Packaging Problem",ISNUMBER(SEARCH("packaging",C22)),"Packaging Problem",ISNUMBER(SEARCH("discoloration",C22)),"Contamination",ISNUMBER(SEARCH("tarnish",C22)),"Contamination",ISNUMBER(SEARCH("stain",C22)),"Contamination",ISNUMBER(SEARCH("foreign material",C22)),"Contamination",ISNUMBER(SEARCH("contamina",C22)),"Contamination",ISNUMBER(SEARCH("overheat",C22)),"Overheating of Device",ISNUMBER(SEARCH("excessive heat",C22)),"Overheating of Device",ISNUMBER(SEARCH("hot",C22)),"Overheating of Device",ISNUMBER(SEARCH("noise",C22)),"Noise, Audible",ISNUMBER(SEARCH("sound",C22)),"Noise, Audible",ISNUMBER(SEARCH("loud",C22)),"Noise, Audible",ISNUMBER(SEARCH("fray",C22)),"Material Frayed",ISNUMBER(SEARCH("hole",C22)),"Material Frayed",ISNUMBER(SEARCH("tear",C22)),"Material Frayed",ISNUMBER(SEARCH("worn",C22)),"Material Frayed",ISNUMBER(SEARCH("intermittent",C22)),"Difficult or Delayed Activation",ISNUMBER(SEARCH("delay",C22)),"Difficult or Delayed Activation",ISNUMBER(SEARCH("label",C22)),"Device Markings/Labelling Problem",ISNUMBER(SEARCH("marking",C22)),"Device Markings/Labelling Problem",ISNUMBER(SEARCH("lacerat",C22)),"Defective Device",ISNUMBER(SEARCH("cut",C22)),"Defective Device",ISNUMBER(SEARCH("leak",C22)),"Fluid/Blood Leak",ISNUMBER(SEARCH("missing",C22)),"Component Missing",ISNUMBER(SEARCH("power",C22)),"Complete Loss of Power",ISNUMBER(SEARCH("will not turn on",C22)),"Complete Loss of Power",ISNUMBER(SEARCH("won't turn on",C22)),"Complete Loss of Power",ISNUMBER(SEARCH("does not turn on",C22)),"Complete Loss of Power",ISNUMBER(SEARCH("electrical",C22)),"Electrical Power Problem",ISNUMBER(SEARCH("pressure",C22)),"Detachment of Device or Device Component",ISNUMBER(SEARCH("slip",C22)),"Detachment of Device or Device Component",ISNUMBER(SEARCH("detach",C22)),"Detachment of Device or Device Component",ISNUMBER(SEARCH("stick",C22)),"Mechanical Jam",ISNUMBER(SEARCH("jam",C22)),"Mechanical Jam",ISNUMBER(SEARCH("rigid",C22)),"Mechanical Jam",ISNUMBER(SEARCH("rust",C22)),"Corroded",ISNUMBER(SEARCH("corrod",C22)),"Corroded",ISNUMBER(SEARCH("corrosion",C22)),"Corroded",ISNUMBER(SEARCH("alignment",C22)),"Defective Device",ISNUMBER(SEARCH("adjust",C22)),"Defective Device",ISNUMBER(SEARCH("perform",C22)),"Defective Device",ISNUMBER(SEARCH("malfunction",C22)),"Defective Device",ISNUMBER(SEARCH("defect",C22)),"Defective Device",ISNUMBER(SEARCH("fail",C22)),"Defective Device",ISNUMBER(SEARCH("not work",C22)),"Defective Device",ISNUMBER(SEARCH("doesn't work",C22)),"Defective Device",TRUE,"UNKNOWN"),"UNKNOWN")))} | F22: =IF(E22="","","No Clinical Signs, Symptoms or Conditions") | G22: =IF(E22="","",IFERROR(VLOOKUP(E22,Codes!$L$2:$N$409,3,FALSE),"—"))
